<?xml version="1.0" encoding="utf-8"?>
<!-- This URDF was automatically created by SolidWorks to URDF Exporter! Originally created by Stephen Brawner (brawner@gmail.com) 
     Commit Version: 1.5.1-0-g916b5db  Build Version: 1.5.7152.31018
     For more information, please see http://wiki.ros.org/sw_urdf_exporter -->
<robot
  name="vehicle">
  <link
    name="base_link">
    <inertial>
      <origin
        xyz="0 0.005 -5.3193E-19"
        rpy="0 0 0" />
      <mass
        value="0.0031416" />
      <inertia
        ixx="1.0472E-07"
        ixy="-3.0355E-40"
        ixz="0"
        iyy="1.5708E-07"
        iyz="2.8699E-40"
        izz="1.0472E-07" />
    </inertial>
    <visual>
      <origin
        xyz="0 0 0"
        rpy="0 0 0" />
      <geometry>
        <mesh
          filename="package://vehicle/meshes/base_link.STL" />
      </geometry>
      <material
        name="">
        <color
          rgba="0.79216 0.81961 0.93333 1" />
      </material>
    </visual>
    <collision>
      <origin
        xyz="0 0 0"
        rpy="0 0 0" />
      <geometry>
        <mesh
          filename="package://vehicle/meshes/base_link.STL" />
      </geometry>
    </collision>
  </link>
  <link
    name="chassis">
    <inertial>
      <origin
        xyz="0.00013502 0.0025003 2.5045"
        rpy="0 0 0" />
      <mass
        value="1020" />
      <inertia
        ixx="1310"
        ixy="-4.5898"
        ixz="-6.4037"
        iyy="15481"
        iyz="-765.78"
        izz="5698.5" />
    </inertial>
    <visual>
      <origin
        xyz="0 0 0"
        rpy="0 0 0" />
      <geometry>
        <mesh
          filename="package://vehicle/meshes/chassis.STL" />
      </geometry>
      <material
        name="">
        <color
          rgba="0.79216 0.81961 0.93333 1" />
      </material>
    </visual>
    <collision>
      <origin
        xyz="0 0 0"
        rpy="0 0 0" />
      <geometry>
        <mesh
          filename="package://vehicle/meshes/chassis.STL" />
      </geometry>
    </collision>
  </link>
  <joint
    name="base_link_connection"
    type="fixed">
    <origin
      xyz="-0.0014967 2.3251 -0.048125"
      rpy="1.5708 0 0" />
    <parent
      link="base_link" />
    <child
      link="chassis" />
    <axis
      xyz="0 0 0" />
  </joint>
  <link
    name="fl_axle">
    <inertial>
      <origin
        xyz="2.2204E-16 -0.15 -0.086266"
        rpy="0 0 0" />
      <mass
        value="5.8054" />
      <inertia
        ixx="0.10756"
        ixy="8.8456E-18"
        ixz="2.4807E-16"
        iyy="0.074472"
        iyz="3.3356E-18"
        izz="0.061438" />
    </inertial>
    <visual>
      <origin
        xyz="0 0 0"
        rpy="0 0 0" />
      <geometry>
        <mesh
          filename="package://vehicle/meshes/fl_axle.STL" />
      </geometry>
      <material
        name="">
        <color
          rgba="0.79216 0.81961 0.93333 1" />
      </material>
    </visual>
    <collision>
      <origin
        xyz="0 0 0"
        rpy="0 0 0" />
      <geometry>
        <mesh
          filename="package://vehicle/meshes/fl_axle.STL" />
      </geometry>
    </collision>
  </link>
  <joint
    name="front_left_steer_joint"
    type="continuous">
    <origin
      xyz="-0.6425 -0.61535 0.5"
      rpy="3.1416 1.3368 3.1416" />
    <parent
      link="chassis" />
    <child
      link="fl_axle" />
    <axis
      xyz="0 1 0" />
  </joint>
  <link
    name="front_left_wheel">
    <inertial>
      <origin
        xyz="6.7998E-06 2.7332E-07 -0.28628"
        rpy="0 0 0" />
      <mass
        value="153.21" />
      <inertia
        ixx="9.1781"
        ixy="-7.6597E-06"
        ixz="-2.2665E-06"
        iyy="9.1785"
        iyz="-5.9075E-06"
        izz="16.054" />
    </inertial>
    <visual>
      <origin
        xyz="0 0 0"
        rpy="0 0 0" />
      <geometry>
        <mesh
          filename="package://vehicle/meshes/front_left_wheel.STL" />
      </geometry>
      <material
        name="">
        <color
          rgba="0.29412 0.29412 0.29412 1" />
      </material>
    </visual>
    <collision>
      <origin
        xyz="0 0 0"
        rpy="0 0 0" />
      <geometry>
        <mesh
          filename="package://vehicle/meshes/front_left_wheel.STL" />
      </geometry>
    </collision>
  </link>
  <joint
    name="front_left_wheel_joint"
    type="continuous">
    <origin
      xyz="0 -0.15 0"
      rpy="0 0 -2.1312" />
    <parent
      link="fl_axle" />
    <child
      link="front_left_wheel" />
    <axis
      xyz="0 0 1" />
  </joint>
  <link
    name="fr_axle">
    <inertial>
      <origin
        xyz="4.4409E-16 -0.15 -0.086266"
        rpy="0 0 0" />
      <mass
        value="5.8054" />
      <inertia
        ixx="0.10756"
        ixy="2.5228E-17"
        ixz="2.6368E-16"
        iyy="0.074472"
        iyz="-1.3996E-17"
        izz="0.061438" />
    </inertial>
    <visual>
      <origin
        xyz="0 0 0"
        rpy="0 0 0" />
      <geometry>
        <mesh
          filename="package://vehicle/meshes/fr_axle.STL" />
      </geometry>
      <material
        name="">
        <color
          rgba="0.79216 0.81961 0.93333 1" />
      </material>
    </visual>
    <collision>
      <origin
        xyz="0 0 0"
        rpy="0 0 0" />
      <geometry>
        <mesh
          filename="package://vehicle/meshes/fr_axle.STL" />
      </geometry>
    </collision>
  </link>
  <joint
    name="front_right_steer_joint"
    type="continuous">
    <origin
      xyz="0.6425 -0.61535 0.5"
      rpy="3.1416 -1.4026 3.1416" />
    <parent
      link="chassis" />
    <child
      link="fr_axle" />
    <axis
      xyz="0 1 0" />
  </joint>
  <link
    name="front_right_wheel">
    <inertial>
      <origin
        xyz="6.8007E-06 2.9085E-07 -0.32034"
        rpy="0 0 0" />
      <mass
        value="153.21" />
      <inertia
        ixx="9.1781"
        ixy="-8.5807E-06"
        ixz="-2.4934E-06"
        iyy="9.1785"
        iyz="-5.8784E-06"
        izz="16.054" />
    </inertial>
    <visual>
      <origin
        xyz="0 0 0"
        rpy="0 0 0" />
      <geometry>
        <mesh
          filename="package://vehicle/meshes/front_right_wheel.STL" />
      </geometry>
      <material
        name="">
        <color
          rgba="0.29412 0.29412 0.29412 1" />
      </material>
    </visual>
    <collision>
      <origin
        xyz="0 0 0"
        rpy="0 0 0" />
      <geometry>
        <mesh
          filename="package://vehicle/meshes/front_right_wheel.STL" />
      </geometry>
    </collision>
  </link>
  <joint
    name="front_right_wheel_joint"
    type="continuous">
    <origin
      xyz="0 -0.15 0.034063"
      rpy="0 0 1.4828" />
    <parent
      link="fr_axle" />
    <child
      link="front_right_wheel" />
    <axis
      xyz="0 0 1" />
  </joint>
  <link
    name="steering_link">
    <inertial>
      <origin
        xyz="2.7126E-05 1.2412 -4.9006E-05"
        rpy="0 0 0" />
      <mass
        value="27.398" />
      <inertia
        ixx="3.1369"
        ixy="0.00049138"
        ixz="0.0001888"
        iyy="1.5651"
        iyz="-0.0008423"
        izz="3.1367" />
    </inertial>
    <visual>
      <origin
        xyz="0 0 0"
        rpy="0 0 0" />
      <geometry>
        <mesh
          filename="package://vehicle/meshes/steering_link.STL" />
      </geometry>
      <material
        name="">
        <color
          rgba="0.79216 0.81961 0.93333 1" />
      </material>
    </visual>
    <collision>
      <origin
        xyz="0 0 0"
        rpy="0 0 0" />
      <geometry>
        <mesh
          filename="package://vehicle/meshes/steering_link.STL" />
      </geometry>
    </collision>
  </link>
  <joint
    name="steering_joint"
    type="continuous">
    <origin
      xyz="-0.62 -0.81197 0.81197"
      rpy="2.3533 0.075776 3.0656" />
    <parent
      link="chassis" />
    <child
      link="steering_link" />
    <axis
      xyz="0 1 0" />
  </joint>
  <link
    name="rear_left_wheel">
    <inertial>
      <origin
        xyz="6.7998E-06 2.7332E-07 -0.16168"
        rpy="0 0 0" />
      <mass
        value="153.21" />
      <inertia
        ixx="9.1781"
        ixy="-7.6597E-06"
        ixz="-2.2665E-06"
        iyy="9.1785"
        iyz="-5.9075E-06"
        izz="16.054" />
    </inertial>
    <visual>
      <origin
        xyz="0 0 0"
        rpy="0 0 0" />
      <geometry>
        <mesh
          filename="package://vehicle/meshes/rear_left_wheel.STL" />
      </geometry>
      <material
        name="">
        <color
          rgba="0.29412 0.29412 0.29412 1" />
      </material>
    </visual>
    <collision>
      <origin
        xyz="0 0 0"
        rpy="0 0 0" />
      <geometry>
        <mesh
          filename="package://vehicle/meshes/rear_left_wheel.STL" />
      </geometry>
    </collision>
  </link>
  <joint
    name="rear_left_wheel_joint"
    type="continuous">
    <origin
      xyz="-0.7671 -0.76535 3.8"
      rpy="-1.5708 -1.052 -1.5708" />
    <parent
      link="chassis" />
    <child
      link="rear_left_wheel" />
    <axis
      xyz="0 0 1" />
  </joint>
  <link
    name="rear_right_wheel">
    <inertial>
      <origin
        xyz="6.7998E-06 2.7332E-07 -0.16168"
        rpy="0 0 0" />
      <mass
        value="153.21" />
      <inertia
        ixx="9.1781"
        ixy="-7.6597E-06"
        ixz="-2.2665E-06"
        iyy="9.1785"
        iyz="-5.9075E-06"
        izz="16.054" />
    </inertial>
    <visual>
      <origin
        xyz="0 0 0"
        rpy="0 0 0" />
      <geometry>
        <mesh
          filename="package://vehicle/meshes/rear_right_wheel.STL" />
      </geometry>
      <material
        name="">
        <color
          rgba="0.29412 0.29412 0.29412 1" />
      </material>
    </visual>
    <collision>
      <origin
        xyz="0 0 0"
        rpy="0 0 0" />
      <geometry>
        <mesh
          filename="package://vehicle/meshes/rear_right_wheel.STL" />
      </geometry>
    </collision>
  </link>
  <joint
    name="rear_right_wheel_joint"
    type="continuous">
    <origin
      xyz="0.7671 -0.76535 3.8"
      rpy="-1.5708 0.24615 1.5708" />
    <parent
      link="chassis" />
    <child
      link="rear_right_wheel" />
    <axis
      xyz="0 0 1" />
  </joint>
</robot>